Workbook

Sheet DRP V2
A1: Stock prévisionnel par article | AA1: 0 | DQ1: 0 | DV1: 0 | HM1: 0 | HR1: 0
B6: SAISIE | G6: INFORMATION
B7: Date | C7: SKU | D7: Location ID | G7: Libellé du SKU | H7: Famille de produit | I7: Nom de la boutique | J7: Unité de commande | K7: Order Lead Time: délai de livraison de la commande (en jours) | L7: Stock de sécurité (en nombre de jours) | M7: MOQ (minimum de quantité à commander)
B8: 44739 | C8: 23393 | D8: 1201 | G8: =IFERROR(IF(ISBLANK($C$8),"-",VLOOKUP($C$8,Article!$A:$B,2,FALSE)),"Saisie Incorrecte") -> CLIPS POUR PLINTHE | H8: =IFERROR(IF(ISBLANK($C$8),"-",VLOOKUP($C$8,Article!$A:$C,3,FALSE)),"Saisie Incorrecte") -> SALLE DE BAINS | I8: =IFERROR(IF(ISBLANK($D$8),"-",VLOOKUP($D$8,Shop!$A:$B,2,FALSE)),"Saisie Incorrecte ou donnée KO") -> LA ROCHELLE | J8: =IFERROR(IF(ISBLANK($C$8),"-",VLOOKUP($C$8,Article!$A:$D,4,FALSE)),"Saisie Incorrecte") -> UVC | K8: =IFERROR(IF(ISBLANK($C$8),"-",VLOOKUP($C$8,Article!$A:$E,5,FALSE)),"Saisie incorrecte") -> 7 | L8: =IFERROR(IF(ISBLANK($C$8),"-",VLOOKUP($C$8,'Article-Paramètre'!$A:$C,3,FALSE)),"Saisie incorrecte") -> 5 | M8: =IFERROR(IF(ISBLANK($C$8),"-",VLOOKUP($C$8,'Article-Paramètre'!$A:$C,2,FALSE)),"Saisie incorrecte") -> 400
B11: COMMANDE À PASSER / PROCHAIN ORDRE PLANIFIÉ | G11: DISTRIBUTION RESSOURCE PLANNING
B12: Date de passation | C12: Date de livraison souhaitée | D12: Quantité recommandée | I12: =IF(ISBLANK(B8),"-",B8) -> 44739 | J12: =IF(ISBLANK($B$8),"-",I12+7) -> 44746 | K12: =IF(ISBLANK($B$8),"-",J12+7) -> 44753 | L12: =IF(ISBLANK($B$8),"-",K12+7) -> 44760 | M12: =IF(ISBLANK($B$8),"-",L12+7) -> 44767 | N12: =IF(ISBLANK($B$8),"-",M12+7) -> 44774 | O12: =IF(ISBLANK($B$8),"-",N12+7) -> 44781 | P12: =IF(ISBLANK($B$8),"-",O12+7) -> 44788
B13: =IFERROR(C13-K8,"-") -> 44732 | C13: {=IFERROR(IF(SUM(I23:P23)=0,"-",IF(I23>0,I12,IF(J23>0,J12,IF(K23>0,K12,INDEX(I12:P23,1,MATCH(0.01,I23:P23,1)+1))))),"-")} -> 44739 | D13: {=IFERROR(IF(I21>0,I21,IF(J21>0,J21,IF(K21>0,K21,INDEX(I21:P21,1,MATCH(0,I21:P21,1)+1)))),"-")} -> 400 | G13: Stock Initial | I13: =IFERROR(IF(OR(ISBLANK($D$8),ISBLANK($C$8)),"-",VLOOKUP($D$8&"-"&$C$8,Stock_S_Encours!$A:$D,4,FALSE)),0) -> 114
G14: Stock projeté | J14: =IFERROR(IF((I13-I19+I20+I21)<0,0,I13-I19+I20+I21),0) -> 412 | K14: =IFERROR(IF((J14-J19+J20+J21)<0,0,J14-J19+J20+J21),0) -> 482 | L14: =IFERROR(IF((K14-K19+K20+K21)<0,0,K14-K19+K20+K21),0) -> 314 | M14: =IFERROR(IF((L14-L19+L20+L21)<0,0,L14-L19+L20+L21),0) -> 418 | N14: =IFERROR(IF((M14-M19+M20+M21)<0,0,M14-M19+M20+M21),0) -> 308 | O14: =IFERROR(IF((N14-N19+N20+N21)<0,0,N14-N19+N20+N21),0) -> 208 | P14: =IFERROR(IF((O14-O19+O20+O21)<0,0,O14-O19+O20+O21),0) -> 103
G15: Stock de sécurité | I15: =IFERROR(($L$8/7)*I19,0) -> 72.857143 | J15: =IFERROR(($L$8/7)*J19,0) -> 252.85714 | K15: =IFERROR(($L$8/7)*K19,0) -> 120 | L15: =IFERROR(($L$8/7)*L19,0) -> 211.42857 | M15: =IFERROR(($L$8/7)*M19,0) -> 78.571429 | N15: =IFERROR(($L$8/7)*N19,0) -> 71.428571 | O15: =IFERROR(($L$8/7)*O19,0) -> 75 | P15: =IFERROR(($L$8/7)*P19,0) -> 175.71429
B16: CHOIX TRANSPORTEUR | G16: Sous-Stock | I16: =IF(I13+I20<I15+I19,(I13+I20)-(I15+I19),0) -> -60.857143 | J16: =IF(J14+J20<J15+J19,(J14+J20)-(J15+J19),0) -> -170.85714 | K16: =IFERROR(IF(((K14+K20)-(K19+K15))>0,0,((K14+K20)-(K19+K15))),"0") -> 0 | L16: =IFERROR(IF(((L14+L20)-(L19+L15))>0,0,((L14+L20)-(L19+L15))),"0") -> -193.42857 | M16: =IFERROR(IF(((M14+M20)-(M19+M15))>0,0,((M14+M20)-(M19+M15))),"0") -> 0 | N16: =IFERROR(IF(((N14+N20)-(N19+N15))>0,0,((N14+N20)-(N19+N15))),"0") -> 0 | O16: =IFERROR(IF(((O14+O20)-(O19+O15))>0,0,((O14+O20)-(O19+O15))),"0") -> 0 | P16: =IFERROR(IF(((P14+P20)-(P19+P15))>0,0,((P14+P20)-(P19+P15))),"0") -> -318.71429
B17: Référence fournisseur | C17: =IFERROR(IF(C13="-","-",VLOOKUP(C8,Article!A:F,6,FALSE)),"-") -> 14673 | G17: Rupture prévisionnelle | I17: =IFERROR(IF(((I13+I20)-I19)>0,0,(I13+I20)-I19),0) -> 0 | J17: =IFERROR(IF(((J14+J20)-J19)>0,0,(J14+J20)-J19),0) -> 0 | K17: =IFERROR(IF(((K14+K20)-K19)>0,0,(K14+K20)-K19),0) -> 0 | L17: =IFERROR(IF(((L14+L20)-L19)>0,0,(L14+L20)-L19),0) -> 0 | M17: =IFERROR(IF(((M14+M20)-M19)>0,0,(M14+M20)-M19),0) -> 0 | N17: =IFERROR(IF(((N14+N20)-N19)>0,0,(N14+N20)-N19),0) -> 0 | O17: =IFERROR(IF(((O14+O20)-O19)>0,0,(O14+O20)-O19),0) -> 0 | P17: =IFERROR(IF(((P14+P20)-P19)>0,0,(P14+P20)-P19),0) -> -143
B18: Distance KM | C18: =IFERROR(VLOOKUP(C17&D8,'Fournisseurs-Magasin'!A:D,4,FALSE),"-") -> 666 | G18: Couverture de Stock | I18: =IF(I13+I20<0,0,IF(SUM($I$13:$P$14)=0,0,IF(I17<0,(1+I17/I19)*7,IF(J17<0,7+(1+J17/J19)*7,IF(K17<0,14+(1+K17/K19)*7,IF(L17<0,21+(1+L17/L19)*7,IF(M17<0,28+(1+M17/M19)*7,IF(N17<0,35+(1+N17/N19)*7,IF(O17<0,42+(1+O17/O19)*7,IF(P17<0,49+(1+P17/P19)*7,56)))))))))) -> 51.930894 | J18: =IF(J13+J20<0,0,IF(SUM($I$13:$P$14)=0,0,IF(J17<0,(1+J17/J19)*7,IF(K17<0,7+(1+K17/K19)*7,IF(L17<0,14+(1+L17/L19)*7,IF(M17<0,21+(1+M17/M19)*7,IF(N17<0,28+(1+N17/N19)*7,IF(O17<0,35+(1+O17/O19)*7,IF(P17<0,42+(1+P17/P19)*7,IF(Q17<0,49+(1+Q17/Q19)*7,56)))))))))) -> 44.930894 | K18: =IF(K13+K20<0,0,IF(SUM($I$13:$P$14)=0,0,IF(K17<0,(1+K17/K19)*7,IF(L17<0,7+(1+L17/L19)*7,IF(M17<0,14+(1+M17/M19)*7,IF(N17<0,21+(1+N17/N19)*7,IF(O17<0,28+(1+O17/O19)*7,IF(P17<0,35+(1+P17/P19)*7,IF(Q17<0,42+(1+Q17/Q19)*7,IF(R17<0,49+(1+R17/R19)*7,56)))))))))) -> 37.930894 | L18: =IF(L13+L20<0,0,IF(SUM($I$13:$P$14)=0,0,IF(L17<0,(1+L17/L19)*7,IF(M17<0,7+(1+M17/M19)*7,IF(N17<0,14+(1+N17/N19)*7,IF(O17<0,21+(1+O17/O19)*7,IF(P17<0,28+(1+P17/P19)*7,IF(Q17<0,35+(1+Q17/Q19)*7,IF(R17<0,42+(1+R17/R19)*7,IF(S17<0,49+(1+S17/S19)*7,56)))))))))) -> 30.930894 | M18: =IF(M13+M20<0,0,IF(SUM($I$13:$P$14)=0,0,IF(M17<0,(1+M17/M19)*7,IF(N17<0,7+(1+N17/N19)*7,IF(O17<0,14+(1+O17/O19)*7,IF(P17<0,21+(1+P17/P19)*7,IF(Q17<0,28+(1+Q17/Q19)*7,IF(R17<0,35+(1+R17/R19)*7,IF(S17<0,42+(1+S17/S19)*7,IF(T17<0,49+(1+T17/T19)*7,56)))))))))) -> 23.930894 | N18: =IF(N13+N20<0,0,IF(SUM($I$13:$P$14)=0,0,IF(N17<0,(1+N17/N19)*7,IF(O17<0,7+(1+O17/O19)*7,IF(P17<0,14+(1+P17/P19)*7,IF(Q17<0,21+(1+Q17/Q19)*7,IF(R17<0,28+(1+R17/R19)*7,IF(S17<0,35+(1+S17/S19)*7,IF(T17<0,42+(1+T17/T19)*7,IF(U17<0,49+(1+U17/U19)*7,56)))))))))) -> 16.930894 | O18: =IF(O13+O20<0,0,IF(SUM($I$13:$P$14)=0,0,IF(O17<0,(1+O17/O19)*7,IF(P17<0,7+(1+P17/P19)*7,IF(Q17<0,14+(1+Q17/Q19)*7,IF(R17<0,21+(1+R17/R19)*7,IF(S17<0,28+(1+S17/S19)*7,IF(T17<0,35+(1+T17/T19)*7,IF(U17<0,42+(1+U17/U19)*7,IF(V17<0,49+(1+V17/V19)*7,56)))))))))) -> 9.9308943 | P18: =IF(P13+P20<0,0,IF(SUM($I$13:$P$14)=0,0,IF(P17<0,(1+P17/P19)*7,IF(Q17<0,7+(1+Q17/Q19)*7,IF(R17<0,14+(1+R17/R19)*7,IF(S17<0,21+(1+S17/S19)*7,IF(T17<0,28+(1+T17/T19)*7,IF(U17<0,35+(1+U17/U19)*7,IF(V17<0,42+(1+V17/V19)*7,IF(W17<0,49+(1+W17/W19)*7,56)))))))))) -> 2.9308943
B19: Nom Transporteur | C19: =IFERROR(INDEX(Table3[],MATCH(1,Table3[Prix Min Transport DRP V2],0),1),"-") -> PL | G19: Demande prévisionnelle | I19: =IFERROR(IF(OR(ISBLANK($C$8),ISBLANK($D$8),ISBLANK(I$12)),"-",VLOOKUP($D$8&"-"&$C$8&"-"&I$12,Forecast!$A:$E,5,FALSE)),0) -> 102 | J19: =IFERROR(IF(OR(ISBLANK($C$8),ISBLANK($D$8),ISBLANK(J$12)),"-",VLOOKUP($D$8&"-"&$C$8&"-"&J$12,Forecast!$A:$E,5,FALSE)),0) -> 354 | K19: =IFERROR(IF(OR(ISBLANK($C$8),ISBLANK($D$8),ISBLANK(K$12)),"-",VLOOKUP($D$8&"-"&$C$8&"-"&K$12,Forecast!$A:$E,5,FALSE)),0) -> 168 | L19: =IFERROR(IF(OR(ISBLANK($C$8),ISBLANK($D$8),ISBLANK(L$12)),"-",VLOOKUP($D$8&"-"&$C$8&"-"&L$12,Forecast!$A:$E,5,FALSE)),0) -> 296 | M19: =IFERROR(IF(OR(ISBLANK($C$8),ISBLANK($D$8),ISBLANK(M$12)),"-",VLOOKUP($D$8&"-"&$C$8&"-"&M$12,Forecast!$A:$E,5,FALSE)),0) -> 110 | N19: =IFERROR(IF(OR(ISBLANK($C$8),ISBLANK($D$8),ISBLANK(N$12)),"-",VLOOKUP($D$8&"-"&$C$8&"-"&N$12,Forecast!$A:$E,5,FALSE)),0) -> 100 | O19: =IFERROR(IF(OR(ISBLANK($C$8),ISBLANK($D$8),ISBLANK(O$12)),"-",VLOOKUP($D$8&"-"&$C$8&"-"&O$12,Forecast!$A:$E,5,FALSE)),0) -> 105 | P19: =IFERROR(IF(OR(ISBLANK($C$8),ISBLANK($D$8),ISBLANK(P$12)),"-",VLOOKUP($D$8&"-"&$C$8&"-"&P$12,Forecast!$A:$E,5,FALSE)),0) -> 246
B20: Coût associé | C20: =IFERROR(INDEX(Table3[],MATCH(1,Table3[Prix Min Transport DRP V2],0),4),"-") -> 740.66 | G20: Ordre Ferme | I20: =IFERROR(IF(OR(ISBLANK($C$8),ISBLANK($D$8),ISBLANK(I$12)),"-",VLOOKUP($D$8&"-"&$C$8&"-"&I$12,Commandes_EnCours!$A:$E,5,FALSE)),0) -> 0 | J20: =IFERROR(IF(OR(ISBLANK($C$8),ISBLANK($D$8),ISBLANK(J$12)),"-",VLOOKUP($D$8&"-"&$C$8&"-"&J$12,Commandes_EnCours!$A:$E,5,FALSE)),0) -> 24 | K20: =IFERROR(IF(OR(ISBLANK($C$8),ISBLANK($D$8),ISBLANK(K$12)),"-",VLOOKUP($D$8&"-"&$C$8&"-"&K$12,Commandes_EnCours!$A:$E,5,FALSE)),0) -> 0 | L20: =IFERROR(IF(OR(ISBLANK($C$8),ISBLANK($D$8),ISBLANK(L$12)),"-",VLOOKUP($D$8&"-"&$C$8&"-"&L$12,Commandes_EnCours!$A:$E,5,FALSE)),0) -> 0 | M20: =IFERROR(IF(OR(ISBLANK($C$8),ISBLANK($D$8),ISBLANK(M$12)),"-",VLOOKUP($D$8&"-"&$C$8&"-"&M$12,Commandes_EnCours!$A:$E,5,FALSE)),0) -> 0 | N20: =IFERROR(IF(OR(ISBLANK($C$8),ISBLANK($D$8),ISBLANK(N$12)),"-",VLOOKUP($D$8&"-"&$C$8&"-"&N$12,Commandes_EnCours!$A:$E,5,FALSE)),0) -> 0 | O20: =IFERROR(IF(OR(ISBLANK($C$8),ISBLANK($D$8),ISBLANK(O$12)),"-",VLOOKUP($D$8&"-"&$C$8&"-"&O$12,Commandes_EnCours!$A:$E,5,FALSE)),0) -> 0 | P20: =IFERROR(IF(OR(ISBLANK($C$8),ISBLANK($D$8),ISBLANK(P$12)),"-",VLOOKUP($D$8&"-"&$C$8&"-"&P$12,Commandes_EnCours!$A:$E,5,FALSE)),0) -> 0
G21: Ordre Planifié | I21: =IF(AND(I23<$M$8,I23>0),$M$8,I23) -> 400 | J21: =IF(AND(J23<$M$8,J23>0),$M$8,J23) -> 400 | K21: =IF(AND(K23<$M$8,K23>0),$M$8,K23) -> 0 | L21: =IF(AND(L23<$M$8,L23>0),$M$8,L23) -> 400 | M21: =IF(AND(M23<$M$8,M23>0),$M$8,M23) -> 0 | N21: =IF(AND(N23<$M$8,N23>0),$M$8,N23) -> 0 | O21: =IF(AND(O23<$M$8,O23>0),$M$8,O23) -> 0 | P21: =IF(AND(P23<$M$8,P23>0),$M$8,P23) -> 400
G22: Besoin Net prévisionnel | I22: =IFERROR(IF((I$17)<0,ABS(I$17),0),0) -> 0 | J22: =IFERROR(IF((J$17)<0,ABS(J$17),0),0) -> 0 | K22: =IFERROR(IF((K$17)<0,ABS(K$17),0),0) -> 0 | L22: =IFERROR(IF((L$17)<0,ABS(L$17),0),0) -> 0 | M22: =IFERROR(IF((M$17)<0,ABS(M$17),0),0) -> 0 | N22: =IFERROR(IF((N$17)<0,ABS(N$17),0),0) -> 0 | O22: =IFERROR(IF((O$17)<0,ABS(O$17),0),0) -> 0 | P22: =IFERROR(IF((P$17)<0,ABS(P$17),0),0) -> 143
G23: Besoin Net | I23: =IFERROR(IF((I$16)<0,ABS(I$16),0),0) -> 60.857143 | J23: =IFERROR(IF((J$16)<0,ABS(J$16),0),0) -> 170.85714 | K23: =IFERROR(IF((K$16)<0,ABS(K$16),0),0) -> 0 | L23: =IFERROR(IF((L$16)<0,ABS(L$16),0),0) -> 193.42857 | M23: =IFERROR(IF((M$16)<0,ABS(M$16),0),0) -> 0 | N23: =IFERROR(IF((N$16)<0,ABS(N$16),0),0) -> 0 | O23: =IFERROR(IF((O$16)<0,ABS(O$16),0),0) -> 0 | P23: =IFERROR(IF((P$16)<0,ABS(P$16),0),0) -> 318.71429
G25: Couverture moyenne | H25: =IFERROR(IF(SUM(I18:P18)=0,"-",AVERAGE(I18:P18)),"-") -> 27.430894
G26: Variation du stock | H26: =IFERROR(P14/I13-1,"-") -> -0.096491228
A43: Encadré principal: informations importantes -Le stock initial correspond au stock de début de la semaine en cours. -La rupture prévisionnelle correspond à la quantité en rupture. Cela signifie que le stock et les ordres fermes de la semaine ne permettent pas de couvrir les sorties prévues. S’il n’y a pas de rupture, alors la valeur doit afficher 0. -La couverture de stock représente la durée (en nombre de jours) entre la date de l’en-tête de colonne et la prochaine rupture. Cela signifie que si votre stock vous permet de couvrir ⅔ de votre demande hebdomadaire avant de tomber en rupture, il faudra compter ⅔ de semaine dans votre couverture de stock. -L'ordre ferme correspond aux commandes déjà passées par le service. -Le besoin net correspond ici à la rupture prévisionnelle en absolu. C’est la quantité à réceptionner sur la semaine pour ne pas tomber en rupture. Il doit être réintégré dans le calcul du stock projeté de la semaine suivante, au même titre que les ordres fermes.

Sheet Article
A1: SKU | B1: LibSKU | C1: LibGFam | D1: UnCommande | E1: OLeadTime | F1: Fournisseur ID
A2: 23393 | B2: CLIPS POUR PLINTHE | C2: SALLE DE BAINS | D2: UVC | E2: 7 | F2: 14673
A3: 26764 | B3: TRINGLE CHROME | C3: SALLE DE BAINS | D3: UVC | E3: 7 | F3: 12576
A4: 53934 | B4: EQUERRE FIXATION | C4: SALLE DE BAINS | D4: UVC | E4: 14 | F4: 14673
A5: 78699 | B5: POIGNEE CHROME | C5: SALLE DE BAINS | D5: UVC | E5: 7 | F5: 14673
A6: 78869 | B6: SACH. PLIANT | C6: SALLE DE BAINS | D6: UVC | E6: 7 | F6: 14673
A7: 115600 | B7: TUBE PVC | C7: SALLE DE BAINS | D7: PIECE | E7: 14 | F7: 15461
A8: 129208 | B8: COUDE PVC | C8: SALLE DE BAINS | D8: UVC | E8: 14 | F8: 15461
A9: 141622 | B9: BONDE LAVABO | C9: SALLE DE BAINS | D9: UVC | E9: 7 | F9: 12576
A10: 141626 | B10: KIT DE FIXATION | C10: SALLE DE BAINS | D10: UVC | E10: 7 | F10: 14673
A11: 141791 | B11: BACHE DE PROTECTION | C11: SALLE DE BAINS | D11: UVC | E11: 14 | F11: 12576
A12: 141846 | B12: MITIGEUR LAVABO | C12: SALLE DE BAINS | D12: UVC | E12: 14 | F12: 12576
A13: 141967 | B13: BONDE DE DOUCHE | C13: SALLE DE BAINS | D13: UVC | E13: 7 | F13: 12576
... A31: 614993 | B31: PLINTHE INOX | C31: CUISINE | D31: UVC | E31: 14 | F31: 12576

Sheet Article-Paramètre
A1: SKU | B1: MOQ | C1: Stock de Securité
A2: 115600 | B2: 34 | C2: 2
A3: 129208 | B3: 20 | C3: 5
A4: 300380 | B4: 34 | C4: 5
A5: 23393 | B5: 400 | C5: 5
A6: 26764 | B6: 56 | C6: 11
A7: 53934 | B7: 38 | C7: 4
A8: 78699 | B8: 36 | C8: 6
A9: 78869 | B9: 12 | C9: 9
A10: 141622 | B10: 10 | C10: 4
A11: 141626 | B11: 30 | C11: 8
A12: 141791 | B12: 18 | C12: 5
A13: 141846 | B13: 58 | C13: 5
... A31: 614993 | B31: 26 | C31: 7

Sheet Shop
A1: Location ID | B1: Lib Location | C1: Distance depuis Entrepôt (km)
A2: 1201 | B2: LA ROCHELLE | C2: 469
A3: 1202 | B3: BAYONNE | C3: 770
A4: 1203 | B4: ARCUEIL | C4: 35
A5: 1204 | B5: NICE ARIANE (Est) | C5: 913
A6: 1205 | B6: VALENCIENNES | C6: 243
A7: 1206 | B7: CREIL | C7: 108
A8: 1207 | B8: LE HAVRE | C8: 231
A9: 1208 | B9: AVIGNON | C9: 661
A10: 1209 | B10: NICE VILLENEUVE LOUBET | C10: 888
A11: 1210 | B11: STRASBOURG NORD | C11: 503
A12: 1211 | B12: TOULON | C12: 809
A13: 1212 | B13: ROUEN | C13: 170
... A19: 1220 | B19: LIMOGES | C19: 388

Sheet Fournisseurs-Magasin
A1: Concatenation | B1: Fournisseur ID | C1: Shop ID | D1: Distance
A2: =Table1[[#This Row],[Fournisseur ID]]&Table1[[#This Row],[Shop ID]] -> 125761201 | B2: 12576 | C2: 1201 | D2: 927
A3: =Table1[[#This Row],[Fournisseur ID]]&Table1[[#This Row],[Shop ID]] -> 125761202 | B3: 12576 | C3: 1202 | D3: 1155
A4: =Table1[[#This Row],[Fournisseur ID]]&Table1[[#This Row],[Shop ID]] -> 125761203 | B4: 12576 | C4: 1203 | D4: 489
A5: =Table1[[#This Row],[Fournisseur ID]]&Table1[[#This Row],[Shop ID]] -> 125761204 | B5: 12576 | C5: 1204 | D5: 787
A6: =Table1[[#This Row],[Fournisseur ID]]&Table1[[#This Row],[Shop ID]] -> 125761205 | B6: 12576 | C6: 1205 | D6: 487
A7: =Table1[[#This Row],[Fournisseur ID]]&Table1[[#This Row],[Shop ID]] -> 125761206 | B7: 12576 | C7: 1206 | D7: 483
A8: =Table1[[#This Row],[Fournisseur ID]]&Table1[[#This Row],[Shop ID]] -> 125761207 | B8: 12576 | C8: 1207 | D8: 697
A9: =Table1[[#This Row],[Fournisseur ID]]&Table1[[#This Row],[Shop ID]] -> 125761208 | B9: 12576 | C9: 1208 | D9: 721
A10: =Table1[[#This Row],[Fournisseur ID]]&Table1[[#This Row],[Shop ID]] -> 125761209 | B10: 12576 | C10: 1209 | D10: 805
A11: =Table1[[#This Row],[Fournisseur ID]]&Table1[[#This Row],[Shop ID]] -> 125761210 | B11: 12576 | C11: 1210 | D11: 3
A12: =Table1[[#This Row],[Fournisseur ID]]&Table1[[#This Row],[Shop ID]] -> 125761211 | B12: 12576 | C12: 1211 | D12: 869
A13: =Table1[[#This Row],[Fournisseur ID]]&Table1[[#This Row],[Shop ID]] -> 125761212 | B13: 12576 | C13: 1212 | D13: 635
... A96: =Table1[[#This Row],[Fournisseur ID]]&Table1[[#This Row],[Shop ID]] -> 167831500 | B96: 16783 | C96: 1500 | D96: 134

Sheet Transporteurs
A1: Transporteur ID | B1: Prix Fixe € | C1: €/km au-delà fixe | D1: Prix transport DRP V2 | E1: Prix Min Transport DRP V2
A2: AFF | B2: 60 | C2: 1.03 | D2: =Table3[[#This Row],[Prix Fixe €]]+Table3[[#This Row],[€/km au-delà fixe]]*'DRP V2'!$C$18 -> 745.98 | E2: =IF(Table3[[#This Row],[Prix transport DRP V2]]=MIN(D:D),1,0) -> 0
A3: AV | B3: 75 | C3: 1 | D3: =Table3[[#This Row],[Prix Fixe €]]+Table3[[#This Row],[€/km au-delà fixe]]*'DRP V2'!$C$18 -> 741 | E3: =IF(Table3[[#This Row],[Prix transport DRP V2]]=MIN(D:D),1,0) -> 0
A4: C | B4: 34 | C4: 1.22 | D4: =Table3[[#This Row],[Prix Fixe €]]+Table3[[#This Row],[€/km au-delà fixe]]*'DRP V2'!$C$18 -> 846.52 | E4: =IF(Table3[[#This Row],[Prix transport DRP V2]]=MIN(D:D),1,0) -> 0
A5: GV | B5: 55 | C5: 1.04 | D5: =Table3[[#This Row],[Prix Fixe €]]+Table3[[#This Row],[€/km au-delà fixe]]*'DRP V2'!$C$18 -> 747.64 | E5: =IF(Table3[[#This Row],[Prix transport DRP V2]]=MIN(D:D),1,0) -> 0
A6: NAV | B6: 45 | C6: 1.2 | D6: =Table3[[#This Row],[Prix Fixe €]]+Table3[[#This Row],[€/km au-delà fixe]]*'DRP V2'!$C$18 -> 844.2 | E6: =IF(Table3[[#This Row],[Prix transport DRP V2]]=MIN(D:D),1,0) -> 0
A7: PL | B7: 68 | C7: 1.01 | D7: =Table3[[#This Row],[Prix Fixe €]]+Table3[[#This Row],[€/km au-delà fixe]]*'DRP V2'!$C$18 -> 740.66 | E7: =IF(Table3[[#This Row],[Prix transport DRP V2]]=MIN(D:D),1,0) -> 1
A8: PALEX | B8: 0 | C8: 1.2 | D8: =Table3[[#This Row],[Prix Fixe €]]+Table3[[#This Row],[€/km au-delà fixe]]*'DRP V2'!$C$18 -> 799.2 | E8: =IF(Table3[[#This Row],[Prix transport DRP V2]]=MIN(D:D),1,0) -> 0
A9: POLE | B9: 15 | C9: 1.23 | D9: =Table3[[#This Row],[Prix Fixe €]]+Table3[[#This Row],[€/km au-delà fixe]]*'DRP V2'!$C$18 -> 834.18 | E9: =IF(Table3[[#This Row],[Prix transport DRP V2]]=MIN(D:D),1,0) -> 0

Sheet Forecast
A1: cle | B1: Location ID | C1: SKU | D1: Date semaine | E1: Demande prévue | F1: cle
A2: 1201-23393-44739 | B2: 1201 | C2: 23393 | D2: 44739 | E2: 102 | F2: =B2&"-"&C2&"-"&INT(D2) -> 1201-23393-44739
A3: 1201-23393-44746 | B3: 1201 | C3: 23393 | D3: 44746 | E3: 354 | F3: =B3&"-"&C3&"-"&INT(D3) -> 1201-23393-44746
A4: 1201-23393-44753 | B4: 1201 | C4: 23393 | D4: 44753 | E4: 168 | F4: =B4&"-"&C4&"-"&INT(D4) -> 1201-23393-44753
A5: 1201-23393-44760 | B5: 1201 | C5: 23393 | D5: 44760 | E5: 296 | F5: =B5&"-"&C5&"-"&INT(D5) -> 1201-23393-44760
A6: 1201-23393-44767 | B6: 1201 | C6: 23393 | D6: 44767 | E6: 110 | F6: =B6&"-"&C6&"-"&INT(D6) -> 1201-23393-44767
A7: 1201-23393-44774 | B7: 1201 | C7: 23393 | D7: 44774 | E7: 100 | F7: =B7&"-"&C7&"-"&INT(D7) -> 1201-23393-44774
A8: 1201-23393-44781 | B8: 1201 | C8: 23393 | D8: 44781 | E8: 105 | F8: =B8&"-"&C8&"-"&INT(D8) -> 1201-23393-44781
A9: 1201-23393-44788 | B9: 1201 | C9: 23393 | D9: 44788 | E9: 246 | F9: =B9&"-"&C9&"-"&INT(D9) -> 1201-23393-44788
A10: 1201-26764-44739 | B10: 1201 | C10: 26764 | D10: 44739 | E10: 111 | F10: =B10&"-"&C10&"-"&INT(D10) -> 1201-26764-44739
A11: 1201-26764-44746 | B11: 1201 | C11: 26764 | D11: 44746 | E11: 106 | F11: =B11&"-"&C11&"-"&INT(D11) -> 1201-26764-44746
A12: 1201-26764-44753 | B12: 1201 | C12: 26764 | D12: 44753 | E12: 138 | F12: =B12&"-"&C12&"-"&INT(D12) -> 1201-26764-44753
A13: 1201-26764-44760 | B13: 1201 | C13: 26764 | D13: 44760 | E13: 107 | F13: =B13&"-"&C13&"-"&INT(D13) -> 1201-26764-44760
... A4102: 1220-614993-44788 | B4102: 1220 | C4102: 614993 | D4102: 44788 | E4102: 6 | F4102: =B4102&"-"&C4102&"-"&INT(D4102) -> 1220-614993-44788

Sheet Commandes_EnCours
A1: cle | B1: Location ID | C1: SKU | D1: Semaine de reception prévue | E1: Quantité Ordre ferme | F1: cle
A2: 1218-78869-44753 | B2: 1218 | C2: 78869 | D2: 44753 | E2: 35 | F2: =B2&"-"&C2&"-"&INT(D2) -> 1218-78869-44753
A3: 1213-78869-44753 | B3: 1213 | C3: 78869 | D3: 44753 | E3: 18 | F3: =B3&"-"&C3&"-"&INT(D3) -> 1213-78869-44753
A4: 1212-78869-44753 | B4: 1212 | C4: 78869 | D4: 44753 | E4: 11 | F4: =B4&"-"&C4&"-"&INT(D4) -> 1212-78869-44753
A5: 1211-78869-44753 | B5: 1211 | C5: 78869 | D5: 44753 | E5: 28 | F5: =B5&"-"&C5&"-"&INT(D5) -> 1211-78869-44753
A6: 1208-78869-44753 | B6: 1208 | C6: 78869 | D6: 44753 | E6: 7 | F6: =B6&"-"&C6&"-"&INT(D6) -> 1208-78869-44753
A7: 1206-78869-44753 | B7: 1206 | C7: 78869 | D7: 44753 | E7: 7 | F7: =B7&"-"&C7&"-"&INT(D7) -> 1206-78869-44753
A8: 1220-78869-44746 | B8: 1220 | C8: 78869 | D8: 44746 | E8: 25 | F8: =B8&"-"&C8&"-"&INT(D8) -> 1220-78869-44746
A9: 1216-78869-44746 | B9: 1216 | C9: 78869 | D9: 44746 | E9: 17 | F9: =B9&"-"&C9&"-"&INT(D9) -> 1216-78869-44746
A10: 1214-78869-44746 | B10: 1214 | C10: 78869 | D10: 44746 | E10: 18 | F10: =B10&"-"&C10&"-"&INT(D10) -> 1214-78869-44746
A11: 1210-78869-44746 | B11: 1210 | C11: 78869 | D11: 44746 | E11: 35 | F11: =B11&"-"&C11&"-"&INT(D11) -> 1210-78869-44746
A12: 1203-78869-44746 | B12: 1203 | C12: 78869 | D12: 44746 | E12: 16 | F12: =B12&"-"&C12&"-"&INT(D12) -> 1203-78869-44746
A13: 1201-78869-44746 | B13: 1201 | C13: 78869 | D13: 44746 | E13: 17 | F13: =B13&"-"&C13&"-"&INT(D13) -> 1201-78869-44746
... A385: 1202-115600-44739 | B385: 1202 | C385: 115600 | D385: 44739 | E385: 29 | F385: =B385&"-"&C385&"-"&INT(D385) -> 1202-115600-44739

Sheet Stock_S_Encours
A1: Cle | B1: Location ID | C1: SKU | D1: Quantité en Stock | E1: Cle
A2: 1201-115600 | B2: 1201 | C2: 115600 | D2: 64 | E2: =B2&"-"&C2 -> 1201-115600
A3: 1201-129208 | B3: 1201 | C3: 129208 | D3: 108 | E3: =B3&"-"&C3 -> 1201-129208
A4: 1201-300380 | B4: 1201 | C4: 300380 | D4: 76 | E4: =B4&"-"&C4 -> 1201-300380
A5: 1201-23393 | B5: 1201 | C5: 23393 | D5: 114 | E5: =B5&"-"&C5 -> 1201-23393
A6: 1201-26764 | B6: 1201 | C6: 26764 | D6: 98 | E6: =B6&"-"&C6 -> 1201-26764
A7: 1201-53934 | B7: 1201 | C7: 53934 | D7: 88 | E7: =B7&"-"&C7 -> 1201-53934
A8: 1201-78699 | B8: 1201 | C8: 78699 | D8: 80 | E8: =B8&"-"&C8 -> 1201-78699
A9: 1201-78869 | B9: 1201 | C9: 78869 | D9: 112 | E9: =B9&"-"&C9 -> 1201-78869
A10: 1201-141622 | B10: 1201 | C10: 141622 | D10: 108 | E10: =B10&"-"&C10 -> 1201-141622
A11: 1201-141626 | B11: 1201 | C11: 141626 | D11: 90 | E11: =B11&"-"&C11 -> 1201-141626
A12: 1201-141791 | B12: 1201 | C12: 141791 | D12: 68 | E12: =B12&"-"&C12 -> 1201-141791
A13: 1201-141846 | B13: 1201 | C13: 141846 | D13: 74 | E13: =B13&"-"&C13 -> 1201-141846
... A510: 1220-614993 | B510: 1220 | C510: 614993 | D510: 78 | E510: =B510&"-"&C510 -> 1220-614993

Sheet DICODATA
A2: Nb : l’ensemble des quantités dans les tables de faits sont consolidées en unité de commande.
A4: Article | B4: Table de dimension
A5: Nom | B5: Type | C5: Desr
A6: SKU | B6: Int | C6: Identifiant article (PK)
A7: LibSKU | B7: String | C7: Libellé de l'article
A8: LibGFam | B8: String | C8: Famille de l'article
A9: UnCommande | B9: String | C9: Unité de commande
A10: OLeadTime | B10: Int | C10: Lead Time de l'article
A12: Shop | B12: Table de dimension
A13: Nom | B13: Type | C13: Desr
A14: Location ID | B14: Int | C14: Identifiant magasin (PK)
A15: Lib Location | B15: String | C15: Nom/localisation du magasin
A16: Distance depuis Entrepôt (km) | B16: Int | C16: Distance entre le magasin et l'entrepôt
A18: Fournisseurs-Magasin | B18: Table de dimension
A19: Nom | B19: Type | C19: Desr
A20: Fournisseur ID | B20: Int | C20: Identifiant Fournisseur (PK)
A21: Shop ID | B21: String | C21: Identifiant magasin (PK)
A22: Distance | B22: Int | C22: Distance entre le magasin et fournisseur
A24: Transporteur | B24: Table de dimension
A25: Nom | B25: Type | C25: Desr
A26: Transporteur ID | B26: Int | C26: Identifiant Transporteur (PK)
A27: Prix Fixe € | B27: Float | C27: Prix fixe en € pour un transport
A28: €/km au-delà fixe | B28: Float | C28: Prix au km en € au-delà du prix fixe
A30: Forecast | B30: Table de faits
A31: Nom | B31: Type | C31: Desr
A32: Location ID | B32: Int | C32: Identifiant boutique (FK)
A33: SKU | B33: Int | C33: Identifiant article (FK)
A34: Date semaine | B34: Date | C34: Semaine représentée par la date du lundi (FK)
A35: Demande prévue | B35: Date | C35: Quantité de vente prévue aggrégée à la semaine
A37: Commandes_EnCours | B37: Table de faits
A38: Nom | B38: Type | C38: Desr
A39: Location ID | B39: Int | C39: Identifiant boutique (FK)
A40: SKU | B40: Int | C40: Identifiant article (FK)
A41: Semaine de reception prévue | B41: Date | C41: Semaine représentée par la date du lundi (FK)
A42: Quantité Ordre ferme | B42: Int | C42: Quantité commandée aggrégée la semaine
A44: Stock_S_Encours | B44: Table de faits
A45: Nom | B45: Type | C45: Desr
A46: Location ID | B46: Int | C46: Identifiant boutique (FK)
A47: SKU | B47: Int | C47: Identifiant article (FK)
A48: Stock | B48: Int | C48: Quantité actuellement en stock (soit le lundi de la premiere semaine d'analyse)
...
